Workbook

Sheet List Variabel
A1: No | B1: Variabel Offstat | C1: Peran Dalam Model | D1: Level Ketersediaan | E1: Periode Update | F1: Landasan Teoritis OffStat | G1: Bisa Di intervensi Pemerintah? | H1: Sudah Terkumpul | I1: Data Citra atau Geospasial | J1: Landasan Teoriris Citra Satelit | K1: Sudah Terkumpul?
A2: 1 | B2: Jumlah Wisatawan | C2: Stock | D2: Kab/Kota, Provinsi (Nusantara) Provinsi (Mancanegara) | E2: Bulanan, Tahunan | G2: Tidak | H2: TRUE | K2: FALSE
A3: 2 | B3: Jumlah Hotel dan Akomodasi | C3: Stock | D3: Kab/Kota, Provinsi | E3: Tahunan | G3: Bisa | H3: TRUE | K3: FALSE
A4: 3 | B4: Jumlah Objek Daya Tarik Wisata | C4: Stock | D4: Kab/Kota, Provinsi | E4: Tahunan | G4: Bisa | H4: TRUE | K4: FALSE
A5: 4 | B5: Tenaga Kerja Pariwisata | C5: Stock | D5: Provinsi | E5: Tahunan | G5: Tidak | H5: TRUE | K5: FALSE
A6: 5 | B6: Lahan Terbangun | C6: Stock | D6: Kab/Kota, Provinsi | E6: Tahunan | G6: Bisa | H6: TRUE | K6: FALSE
A7: 6 | B7: Laju Kedatangan Wisatawan | C7: Flow | D7: N/A (Model-Generated) | E7: N/A (endogen) | G7: Tidak | H7: TRUE | K7: FALSE
A8: 7 | B8: Laju Penurunan Wisatawan | C8: Flow | D8: N/A (Model-Generated) | E8: N/A (endogen) | G8: Tidak | H8: TRUE | K8: FALSE
A9: 8 | B9: Laju Konstruksi Hotel dan Akomodasi | C9: Flow | D9: N/A (Model-Generated) | E9: N/A (endogen) | G9: Tidak | H9: TRUE | K9: FALSE
A10: 9 | B10: Laju Demolisi Hotel dan Akomodasi | C10: Flow | D10: N/A (Model-Generated) | E10: N/A (endogen) | G10: Tidak | H10: TRUE | K10: FALSE
A11: 10 | B11: Laju Pembangunan/Penambahan ODTW | C11: Flow | D11: N/A (Model-Generated) | E11: N/A (endogen) | G11: Tidak | H11: TRUE | K11: FALSE
A12: 11 | B12: Laju Penutupan ODTW | C12: Flow | D12: N/A (Model-Generated) | E12: N/A (endogen) | G12: Bisa | H12: TRUE | K12: FALSE
A13: 12 | B13: Laju Penyerapan Tenaga Kerja Pariwisata | C13: Flow | D13: N/A (Model-Generated) | E13: N/A (endogen) | F13: Sterman (2000) — stock management | G13: Tidak | H13: TRUE | K13: FALSE
A14: 13 | B14: Laju Keluar Tenaga Kerja Pariwisata | C14: Flow | D14: N/A (Model-Generated) | E14: N/A (endogen) | G14: Tidak | H14: TRUE | K14: FALSE
A15: 14 | B15: Laju Konversi Lahan Pariwisata ke Lahan Terbangun | C15: Flow | D15: N/A (Model-Generated) | E15: N/A (endogen) | G15: Tidak | H15: TRUE | K15: FALSE
A16: 15 | B16: PDRB Pariwisata | C16: Aux | D16: Kab/Kota, Provinsi | E16: Triwulanan, Tahunan | G16: Tidak | H16: TRUE | K16: FALSE
A17: 16 | B17: Total Malam Menginap | C17: Aux | D17: Provinsi | E17: Bulanan, Tahunan | G17: Tidak | H17: TRUE | K17: FALSE
A18: 17 | B18: Pengeluaran Wisatawan | C18: Aux | D18: Provinsi | E18: Tahunan | F18: 1. https://ejurnalunsam.id/index.php/jseb/article/view/11105/5315 | G18: Tidak | H18: TRUE | K18: FALSE
A19: 18 | B19: Tingkat Penghunian Kamar (TPK) | C19: Aux | D19: Kab/Kota, Provinsi | E19: Bulanan, Tahunan | F19: Wheaton & Rossoff (1998); definisi TPK BPS | G19: Tidak | H19: TRUE | K19: FALSE
A20: 19 | B20: Investasi Sektor Pariwisata | C20: Aux | D20: Provinsi (BKPM) | E20: Tahunan | G20: Bisa | H20: TRUE | K20: FALSE
A21: 20 | B21: Daya Tarik Destinasi Wisata | C21: Aux | D21: N/A (Model-Generated) | E21: N/A (endogen) | F21: Sterman (2000) dan Ritchie & Crouch (2003) | G21: Tidak | H21: TRUE | K21: FALSE
A22: 21 | B22: Kepadatan Wisatawan | C22: Aux | D22: N/A (Model-Generated) | E22: N/A (endogen) | F22: McElroy & de Albuquerque (1998) dan Butler (1980) | G22: Tidak | H22: TRUE | K22: FALSE
A23: 22 | B23: Rasio Daya Dukung Lahan | C23: Aux | D23: N/A (Model-Generated) | E23: N/A (endogen) | G23: Tidak | H23: TRUE | K23: FALSE
A24: 23 | B24: Intensitas Tenaga Kerja | C24: Aux | D24: N/A (Model-Generated) | E24: N/A (endogen) | F24: OECD (2001); ILO KILM (output per worker) | G24: Tidak | H24: TRUE | K24: FALSE
A25: 24 | B25: Tenaga Kerja Dibutuhkan | C25: Aux | D25: N/A (Model-Generated) | E25: N/A (endogen) | F25: Hamermesh (1993) — permintaan tenaga kerja turunan | G25: Tidak | H25: TRUE | K25: FALSE
A26: 25 | B26: Rasio Permintaan terhadap Kapasitas Kamar | C26: Aux | D26: N/A (Model-Generated) | E26: N/A (endogen) | F26: Sterman 2000 — stock management | G26: Tidak | H26: TRUE | K26: FALSE
A27: 26 | B27: Rata-rata lama menginap tamu | C27: Parameter | D27: Provinsi | E27: Bulanan, Tahunan | G27: Tidak | H27: TRUE
A28: 27 | B28: Laju Pertumbuhan Eksternal (Wisatawan) | C28: Parameter | D28: derivasi dari data provinsi | E28: Tahunan (kalibrasi) | G28: Bisa | H28: TRUE | K28: FALSE
A29: 28 | B29: Pengeluaran per Kunjungan | C29: Parameter | D29: Nasional (sumbernya BPS RI) | E29: Tahunan | G29: Tidak | H29: TRUE | K29: FALSE
A30: 29 | B30: Rasio Nilai Tambah Pariwisata | C30: Parameter | D30: Nasional | E30: Periodik | G30: Tidak | H30: TRUE | K30: FALSE
A31: 30 | B31: Sensitivitas Konstruksi terhadap TPK | C31: Parameter | D31: derivasi dari data provinsi | E31: Tahunan (kalibrasi) | G31: Tidak | H31: TRUE | K31: FALSE
A32: 31 | B32: TPK Ambang | C32: Parameter | D32: derivasi dari data provinsi | E32: Tahunan (kalibrasi) | G32: Tidak | H32: TRUE | K32: FALSE
A33: 32 | B33: Laju Demolisi Dasar | C33: Parameter | D33: asumsi (triangulasi rujukan dan data provinsi) | E33: Tahunan (kalibrasi) | F33: laju keluar = 1 ÷ rata-rata umur (Sterman, 2000, Bab 6), sama seperti Laju Penutupan Dasar ODTW. | G33: Tidak | H33: TRUE | K33: FALSE
A34: 33 | B34: Rasio Investasi terhadap PDRB | C34: Parameter | D34: derivasi dari data provinsi | E34: Tahunan (kalibrasi) | F34: investasi sebagai proporsi tetap dari output, seperti dalam model pertumbuhan Harrod-Domar. Di SD ini adalah bentuk paling sederhana dari loop ekonomi–investasi (R2). | G34: Tidak | H34: TRUE | K34: FALSE
A35: 34 | B35: Insentif Kebijakan | C35: Parameter | D35: ditetapkan per skenario | E35: Tetap per skenario | G35: Bisa | H35: TRUE | K35: FALSE
A36: 35 | B36: Intensitas Tenaga Kerja Awal | C36: Parameter | D36: derivasi dari data provinsi (tahun dasar 2025) | E36: Tetap (tahun dasar) | F36: OECD (2001); koefisien tenaga kerja (Tabel Input-Output BPS) | G36: Tidak | H36: TRUE | K36: FALSE
A37: 36 | B37: Laju Keluar Dasar Tenaga Kerja | C37: Parameter | D37: asumsi (rujukan teori) | E37: Tahunan (kalibrasi) | G37: Tidak | H37: TRUE | K37: FALSE
A38: 37 | B38: Sensitivitas ODTW terhadap Investasi | C38: Parameter | D38: derivasi dari data provinsi | E38: Tahunan (kalibrasi) | G38: Tidak | H38: TRUE | K38: FALSE
A39: 38 | B39: Laju Pembangunan ODTW Non Investasi | C39: Parameter | D39: derivasi dari data provinsi | E39: Tahunan (kalibrasi) | G39: Bisa | H39: TRUE | K39: FALSE
A40: 39 | B40: Laju Penutupan Dasar ODTW | C40: Parameter | D40: derivasi dari data provinsi | E40: Tahunan (kalibrasi) | G40: Tidak | H40: TRUE | K40: FALSE
...

Sheet Data Tahunan
A1: No | B1: Variabel Offstat | C1: Peran Dalam Model | D1: Satuan | E1: 2015 | F1: 2016 | G1: 2017 | H1: 2018 | I1: 2019 | J1: 2020 | K1: 2021 | L1: 2022 | M1: 2023 | N1: 2024 | O1: 2025 | P1: Sumber | Q1: Link Sumber | R1: Catatan | S1: Temuan
A2: 1 | B2: Jumlah Wisatawan | C2: Stock | D2: Kunjungan | E2: =E3+E4 -> 6413735 | F2: =F3+F4 -> 6551294 | G2: =G3+G4 -> 6644412 | H2: =H3+H4 -> 7996959 | I2: =I3+I4 -> 20520104 | J2: =J3+J4 -> 19610135 | K2: =K3+K4 -> 22849394 | L2: =L3+L4 -> 25755726 | ... O2: =O3+O4 -> 40695654 | P2: Publikasi wisatawan mancanegara dan nusantara
B3: Jumlah Wisatawan Nusantara | C3: Data pendukung | D3: Perjalanan | E3: 6331609 | F3: 6436655 | G3: 6498739 | H3: 7858137 | I3: 20407076 | J3: 19591482 | K3: 22834000 | L3: 25743590 | M3: 30437069 | N3: 38030739 | O3: 40592837 | P3: Publikasi wisatawan nusantara
B4: Jumlah Wisatawan Mancanegara | C4: Data pendukung | D4: Kunjungan | E4: 82126 | F4: 114639 | G4: 145673 | H4: 138822 | I4: 113028 | J4: 18653 | K4: =J4+((L4-J4)/(2022-2020))* (2021-2020) -> 15394.5 | L4: 12136 | M4: 105511 | N4: 103797 | O4: 102817 | P4: Publikasi wisatawan mancanegara
A5: 2 | B5: Jumlah Hotel dan Akomodasi Lainnya | C5: Stock | D5: Unit Akomodasi | E5: =E6+E7 -> 1165 | F5: =F6+F7 -> 1170 | G5: =G6+G7 -> 1179 | H5: =H6+H7 -> 1617 | I5: =I6+I7 -> 1817 | J5: =J6+J7 -> 1848 | K5: =K6+K7 -> 1696 | L5: =L6+L7 -> 1818 | ... O5: =O6+O7 -> 2291 | P5: Publikasi Statistik Hotel dan Akomodasi Lainnya, BPS
B6: Jumlah Hotel Bintang | C6: Data pendukung | D6: Unit Akomodasi | E6: 89 | F6: 94 | G6: 117 | H6: 143 | I6: 163 | J6: 172 | K6: 168 | L6: 192 | M6: 193 | N6: 207 | O6: 222 | P6: Publikasi Statistik Hotel dan Akomodasi Lainnya, BPS
B7: Jumlah Hoten non bintang dan akomodasi lainnya | C7: Data pendukung | D7: Unit Akomodasi | E7: 1076 | F7: 1076 | G7: 1062 | H7: 1474 | I7: 1654 | J7: 1676 | K7: 1528 | L7: 1626 | M7: 1627 | N7: 1793 | O7: 2069 | P7: Publikasi Statistik Hotel dan Akomodasi Lainnya, BPS
A8: 3 | B8: Jumlah Objek Daya Tarik Wisata | C8: Stock | D8: Unit | E8: 165 | F8: 158 | G8: 171 | H8: 177 | I8: 189 | J8: 180 | K8: 170 | L8: 183 | M8: 201 | N8: 218 | O8: 201 | P8: Publikasi ODTW BPS dan Estimasi menggunakan NTL (2015-2017 DAN 2025) | R8: 2018–2024 dari Publikasi Statistik ODTW BPS; 2015–2017 dan 2025 estimasi berbasis NTL (VIIRS DNB) karena publikasi BPS terbaru baru memuat data 2024. Model regresi first-difference NTL–ODTW (R² ≈ 0,41; RMSE LOOCV ≈ 6%). Estimasi 2025 menunjukkan penurunan 218 → 201 yang tidak sejalan dengan indikator pariwisata lain dan hanya sedikit di atas 1 RMSE; parameter ODTW diuji dengan nilai 2025 sebesar 189–218. Diperbarui jika data BPS 2025 dirilis.
B10: Jumlah Objek Wisata (DDA) | C10: Data pendukung | D10: Objek | E10: 176 | F10: 135 | G10: 149 | H10: 186 | I10: 223 | J10: 228 | K10: 191 | L10: 191 | N10: 382 | O10: 388 | P10: Publikasi Daerah Istimewa Yogyakarta Dalam Angka, BPS | Q10: https://yogyakarta.bps.go.id/id/publication/2026/02/27/77355be26097c9f6197b0ef9/provinsi-di-yogyakarta-dalam-angka-2026.html
B11: Tenaga Kerja Pariwisata (Kemenpar) | C11: Data pendukung | D11: Jiwa | H11: 400541 | I11: 414689 | J11: 354897 | K11: 387213 | L11: 439029 | M11: 471212 | N11: 455412 | P11: Kementerian Pariwisata | Q11: https://satudata.kemenpar.go.id/dataset/jumlah-tenaga-kerja-pariwisata
B12: Tenaga Kerja (ODTW) *tidak usah dipakai | C12: Data pendukung | D12: Jiwa | H12: 3898 | I12: 4604 | J12: 3724 | K12: 3969 | L12: 3632 | N12: 5040 | P12: Publikasi Objek Daya Tarik Wisata, BPS | Q12: https://www.bps.go.id/id/publication/2024/12/20/ebca1af66c31bbdf2b912be9/statistik-objek-daya-tarik-wisata-2023.html
A13: 4 | B13: Tenaga Kerja (Based on KBLI I & R,S,T,U) | C13: Stock | D13: Jiwa | E13: 254537 | F13: 263878 | G13: =151687+121876 -> 273563 | H13: =143309+211375 -> 354684 | I13: =130357+204427 -> 334784 | J13: =138570+175270 -> 313840 | K13: =188484+122271 -> 310755 | L13: =255614+139670 -> 395284 | M13: =122273+237067 -> 359340 | N13: =227695+123251 -> 350946 | O13: =242091+122903 -> 364994 | P13: Publikasi Daerah Istimewa Yogyakarta Dalam Angka, BPS | Q13: https://yogyakarta.bps.go.id/id/publication/2025/02/28/62dc9b4620317fb350b9ba3e/provinsi-daerah-istimewa-yogyakarta-dalam-angka-2025.html
B14: Tenaga Kerja (G, H, I, J, K, L, N, P, R (atau R,S) | C14: Data pendukung | D14: Jiwa | G14: =305695+44252+151687+14956+25493+2766+39383+90097+121876 -> 796205 | H14: =400523+77533+211375+16286+34573+1964+51008+118798+143309 -> 1055369 | I14: =412955+86084+204427+21623+33621+1506+53133+148993+130357 -> 1092699 | J14: =446907+73120+175270+30291+28906+3418+34209+130798+138570 -> 1061489 | K14: =489500+70976+188484+29747+31003+4839+41755+138121+122271 -> 1116696 | L14: =444742+100671+225614+22693+24400+4693+52282+141321+139670 -> 1156086 | M14: =445522+80453+237067+21136+27788+3867+65827+143118+122273 -> 1147051 | N14: =430550+86081+227695+21458+28211+5923+62708+131777+123251 -> 1117654 | O14: =422756+83946+242091+26409+32154+66926+131870+122903+5660 -> 1134715 | P14: Publikasi Daerah Istimewa Yogyakarta Dalam Angka, BPS | Q14: https://yogyakarta.bps.go.id/id/publication/2025/02/28/62dc9b4620317fb350b9ba3e/provinsi-daerah-istimewa-yogyakarta-dalam-angka-2025.html
A15: 5 | B15: Lahan Terbangun (DynamicWorld) | C15: Stock | D15: Hektar | E15: {=F15/INDEX(LOGEST(F15:O15),1,1)} -> 43037.005 | F15: 44561.078 | G15: 50223.957 | H15: 56624.36 | I15: 63480.044 | J15: 58962.041 | K15: 59887.526 | L15: 57709.076 | M15: 75624.404 | N15: 73511.575 | O15: 55029.535 | P15: Data Citra Dynamic world - Built Up Area | R15: 2015 = imputasi ekstrapolasi mundur: Lahan Terbangun 2016 ÷ faktor pertumbuhan tren log-linear DW 2016–2025, karena citra Sentinel-2 (basis Dynamic World) baru tersedia sejak pertengahan 2015 dengan jumlah citra sangat terbatas. Bukan observasi; tidak dipakai untuk menurunkan parameter dan dikeluarkan dari statistik uji perilaku.
B16: Lahan Terbangun (BPS) | C16: Data pendukung | D16: Hektar | E16: 76334 | F16: 77467 | G16: 108580 | H16: 114942 | I16: 70371.45 | P16: BPS, Lahan Bukan Pertanian (jalan pemukiman, perkantoran, dll), tahun 2017-2019 itu dari publikasi DLHK DIY sumber yang tercantumnya dari BPS DIY) | Q16: https://yogyakarta.bps.go.id/id/statistics-table/2/MjM3IzI=/luas-penggunaan-lahan-pertanian-dan-bukan-pertanian-di-d-i--yogyakarta--hektar-.html https://dlhk.jogjaprov.go.id/wp-content/uploads/2025/03/Buku-Data-IKPLHD-DIY-2019.pdf
B17: Lahan Terbangun (DLHK DIY) | C17: Data pendukung | D17: Hektar | E17: 75146 | F17: 65460.72 | G17: 70371.45 | H17: 70371.45 | P17: Badan Lingkungan Hidup DIY | Q17: https://dlhk.jogjaprov.go.id/ikplhd/
A18: 6 | B18: Laju Kedatangan Wisatawan | C18: Flow | D18: Kunjungan/Tahun | F18: =(F2-E2)+F19 -> 1429799.6 | G18: =(G2-F2)+G19 -> 1413074 | H18: =(H2-G2)+H19 -> 2691264.5 | I18: =(I2-H2)+I19 -> 14134374 | J18: =(J2-I2)+J19 -> 3224425.7 | K18: =(K2-J2)+K19 -> 7190313.5 | L18: =(L2-K2)+L19 -> 7510032.1 | M18: =(M2-L2)+M19 -> 9976122.9 | ... O18: =(O2-N2)+O19 -> 10244472 | P18: Diolah dengan identitas stock-flow: Δstok + flow keluar | R18: Seri tersirat, bukan observasi. Di model: Jumlah Wisatawan × Laju Pertumbuhan Eksternal × Daya Tarik. Nilai 2019 dipengaruhi patahan metode data wisatawan nusantara BPS.
A19: 7 | B19: Laju Penurunan Wisatawan | C19: Flow | D19: Kunjungan/Tahun | F19: =$O$67*E2 -> 1292240.6 | G19: =$O$67*F2 -> 1319956 | H19: =$O$67*G2 -> 1338717.5 | I19: =$O$67*H2 -> 1611228.9 | J19: =$O$67*I2 -> 4134394.7 | K19: =$O$67*J2 -> 3951054 | L19: =$O$67*K2 -> 4603700.6 | M19: =$O$67*L2 -> 5189268.9 | ... O19: =$O$67*N2 -> 7683354 | P19: Diolah: parameter laju × stok tahun sebelumnya | R19: Keluar orde pertama (Sterman, 2000). Menggambarkan berkurangnya tingkat kunjungan tahunan.
A20: 8 | B20: Laju Konstruksi Hotel dan Akomodasi | C20: Flow | D20: Unit Akomodasi/Tahun | F20: =(F5-E5)+F21 -> 63.25 | G20: =(G5-F5)+G21 -> 67.5 | H20: =(H5-G5)+H21 -> 496.95 | I20: =(I5-H5)+I21 -> 280.85 | J20: =(J5-I5)+J21 -> 121.85 | K20: =(K5-J5)+K21 -> -59.6 | L20: =(L5-K5)+L21 -> 206.8 | M20: =(M5-L5)+M21 -> 92.9 | ... O20: =(O5-N5)+O21 -> 391 | P20: Diolah dengan identitas stock-flow: ΔHotel + Laju Demolisi Dasar × Hotel tahun sebelumnya | R20: Seri tersirat dari data, bukan observasi langsung. Di model: Investasi × Sensitivitas Konstruksi × MAX(0, TPK − TPK Ambang). Nilai negatif 2021 menunjukkan penutupan akibat COVID melebihi laju demolisi rata-rata.
A21: 9 | B21: Laju Demolisi Hotel dan Akomodasi | C21: Flow | D21: Unit Akomodasi/Tahun | F21: =$O$47*E5 -> 58.25 | G21: =$O$47*F5 -> 58.5 | H21: =$O$47*G5 -> 58.95 | I21: =$O$47*H5 -> 80.85 | J21: =$O$47*I5 -> 90.85 | K21: =$O$47*J5 -> 92.4 | L21: =$O$47*K5 -> 84.8 | M21: =$O$47*L5 -> 90.9 | ... O21: =$O$47*N5 -> 100 | P21: Diolah: parameter laju × stok tahun sebelumnya | R21: Keluar orde pertama; rata-rata umur operasi akomodasi ±20 tahun.
A22: 10 | B22: Laju Pembangunan/Penambahan ODTW | C22: Flow | D22: Unit/Tahun | F22: =(F8-E8)+F23 -> 1.2388946 | G22: =(G8-F8)+G23 -> 20.889366 | H22: =(H8-G8)+H23 -> 14.538491 | I22: =(I8-H8)+I23 -> 20.838087 | J22: =(J8-I8)+J23 -> 0.43727926 | K22: =(K8-J8)+K23 -> -1.012115 | L22: =(L8-K8)+L23 -> 21.488558 | M22: =(M8-L8)+M23 -> 27.137683 | ... O22: =(O8-N8)+O23 -> -6.1146726 | P22: Diolah dengan identitas stock-flow: ΔODTW + Laju Penutupan Dasar ODTW × ODTW tahun sebelumnya | R22: Seri tersirat. Di model: Investasi × Sensitivitas ODTW terhadap Investasi + Laju Pembangunan ODTW Non Investasi. Nilai negatif 2025 menunjukkan penutupan di atas laju rata-rata
A23: 11 | B23: Laju Penutupan ODTW | C23: Flow | D23: Unit/Tahun | F23: =$O$54*E8 -> 8.2388946 | G23: =$O$54*F8 -> 7.8893657 | H23: =$O$54*G8 -> 8.5384908 | I23: =$O$54*H8 -> 8.8380869 | J23: =$O$54*I8 -> 9.4372793 | K23: =$O$54*J8 -> 8.987885 | L23: =$O$54*K8 -> 8.4885581 | M23: =$O$54*L8 -> 9.1376831 | ... O23: =$O$54*N8 -> 10.885327 | P23: Diolah: parameter laju × stok tahun sebelumnya | R23: Keluar orde pertama; rata-rata umur usaha ODTW ±20 tahun.
A24: 12 | B24: Laju Penyerapan Tenaga Kerja Pariwisata | C24: Flow | D24: Jiwa/Tahun | F24: =(F13-E13)+F25 -> 16977.11 | G24: =(G13-F13)+G25 -> 17601.34 | H24: =(H13-G13)+H25 -> 89327.89 | I24: =(I13-H13)+I25 -> -9259.48 | J24: =(J13-I13)+J25 -> -10900.48 | K24: =(K13-J13)+K25 -> 6330.2 | L24: =(L13-K13)+L25 -> 93851.65 | M24: =(M13-L13)+M25 -> -24085.48 | ... O24: =(O13-N13)+O25 -> 24576.38 | P24: Diolah dengan identitas stock-flow: Δstok + flow keluar | R24: Seri tersirat dari identitas stock-flow, bisa negatif akibat fluktuasi data Sakernas. Di model: MAX(0, Laju Keluar TK + (Tenaga Kerja Dibutuhkan − Tenaga Kerja Pariwisata) ÷ Waktu Penyesuaian Tenaga Kerja), yaitu penggantian pekerja keluar ditambah koreksi selisih (stock management; Sterman, 2000).
A25: 13 | B25: Laju Keluar Tenaga Kerja Pariwisata | C25: Flow | D25: Jiwa/Tahun | F25: =$O$51*E13 -> 7636.11 | G25: =$O$51*F13 -> 7916.34 | H25: =$O$51*G13 -> 8206.89 | I25: =$O$51*H13 -> 10640.52 | J25: =$O$51*I13 -> 10043.52 | K25: =$O$51*J13 -> 9415.2 | L25: =$O$51*K13 -> 9322.65 | M25: =$O$51*L13 -> 11858.52 | ... O25: =$O$51*N13 -> 10528.38 | P25: Diolah: parameter laju × stok tahun sebelumnya | R25: Keluar orde pertama; masa kerja rata-rata ±34 tahun.
A26: 14 | B26: Laju Konversi Lahan Pariwisata ke Lahan Terbangun | C26: Flow | D26: Hektar/Tahun | F26: =MAX(0,(F20*$O$61+F22*$O$62)*(1-$O$74)) -> 6.9444473 | G26: =MAX(0,(G20*$O$61+G22*$O$62)*(1-$O$74)) -> 17.194683 | H26: =MAX(0,(H20*$O$61+H22*$O$62)*(1-$O$74)) -> 56.964245 | I26: =MAX(0,(I20*$O$61+I22*$O$62)*(1-$O$74)) -> 38.504043 | J26: =MAX(0,(J20*$O$61+J22*$O$62)*(1-$O$74)) -> 12.40364 | K26: =MAX(0,(K20*$O$61+K22*$O$62)*(1-$O$74)) -> 0 | L26: =MAX(0,(L20*$O$61+L22*$O$62)*(1-$O$74)) -> 31.424279 | M26: =MAX(0,(M20*$O$61+M22*$O$62)*(1-$O$74)) -> 22.858842 | ... O26: =MAX(0,(O20*$O$61+O22*$O$62)*(1-$O$74)) -> 36.042664 | P26: Diolah dari seri konstruksi hotel dan pembangunan ODTW tersirat × Lahan per Hotel dan Lahan per ODTW | R26: Luas lahan terbangun baru akibat pembangunan akomodasi dan ODTW (pendekatan koefisien kebutuhan lahan). Memakai laju bruto karena lahan tidak kembali saat usaha tutup. Dibatasi minimal 0. Porsi ±2,4% dari perubahan Lahan Terbangun DW 2017–2025. Kebijakan Konservasi Lahan historis = 0. model dikalikan faktor ketersediaan lahan (Rasio Daya Dukung ÷ Rasio Referensi)
A27: 15 | B27: PDRB ADHK Pariwisata (I & R,S,T,U) | C27: Aux | D27: Miliar Rupiah | E27: =('PDRB DIY'!M50+'PDRB DIY'!M64) -> 10131.09 | F27: =('PDRB DIY'!N50+'PDRB DIY'!N64) -> 10694.03 | G27: =('PDRB DIY'!O50+'PDRB DIY'!O64) -> 11347.59 | H27: =('PDRB DIY'!P50+'PDRB DIY'!P64) -> 12100.99 | I27: =('PDRB DIY'!Q50+'PDRB DIY'!Q64) -> 13104.38 | J27: =('PDRB DIY'!R50+'PDRB DIY'!R64) -> 10926.83 | K27: =('PDRB DIY'!S50+'PDRB DIY'!S64) -> 12097.19 | L27: =('PDRB DIY'!T50+'PDRB DIY'!T64) -> 13672.58 | ... O27: =('PDRB DIY'!W50+'PDRB DIY'!W64) -> 16947.62 | P27: BPS Provinsi DIY | Q27: https://yogyakarta.bps.go.id/id/statistics-table/3/VWtsTFNuRlpabk16TWxKaVNXcE1PRXhKT0RJclFUMDkjMyMzNDAw/produk-domestik-regional-bruto-atas-dasar-harga-konstan-2010-menurut-lapangan-usaha-di-provinsi-di-yogyakarta--miliar-rupiah-.html?year=2025
B28: PDRB ADHK Pariwisata (G, H, I, J, K, L, N, P, R (atau R,S)) | C28: Data pendukung | D28: Milliar Rupiah | E28: =('PDRB DIY'!M42+'PDRB DIY'!M50+'PDRB DIY'!M53+'PDRB DIY'!M57+'PDRB DIY'!M59+'PDRB DIY'!M60+'PDRB DIY'!M62+'PDRB DIY'!M63+'PDRB DIY'!M64) -> 42138.75 | F28: =('PDRB DIY'!N42+'PDRB DIY'!N50+'PDRB DIY'!N53+'PDRB DIY'!N57+'PDRB DIY'!N59+'PDRB DIY'!N60+'PDRB DIY'!N62+'PDRB DIY'!N63+'PDRB DIY'!N64) -> 44498.6 | G28: =('PDRB DIY'!O42+'PDRB DIY'!O50+'PDRB DIY'!O53+'PDRB DIY'!O57+'PDRB DIY'!O59+'PDRB DIY'!O60+'PDRB DIY'!O62+'PDRB DIY'!O63+'PDRB DIY'!O64) -> 47070.14 | H28: =('PDRB DIY'!P42+'PDRB DIY'!P50+'PDRB DIY'!P53+'PDRB DIY'!P57+'PDRB DIY'!P59+'PDRB DIY'!P60+'PDRB DIY'!P62+'PDRB DIY'!P63+'PDRB DIY'!P64) -> 49957.33 | I28: =('PDRB DIY'!Q42+'PDRB DIY'!Q50+'PDRB DIY'!Q53+'PDRB DIY'!Q57+'PDRB DIY'!Q59+'PDRB DIY'!Q60+'PDRB DIY'!Q62+'PDRB DIY'!Q63+'PDRB DIY'!Q64) -> 53420.19 | J28: =('PDRB DIY'!R42+'PDRB DIY'!R50+'PDRB DIY'!R53+'PDRB DIY'!R57+'PDRB DIY'!R59+'PDRB DIY'!R60+'PDRB DIY'!R62+'PDRB DIY'!R63+'PDRB DIY'!R64) -> 54233.09 | K28: =('PDRB DIY'!S42+'PDRB DIY'!S50+'PDRB DIY'!S53+'PDRB DIY'!S57+'PDRB DIY'!S59+'PDRB DIY'!S60+'PDRB DIY'!S62+'PDRB DIY'!S63+'PDRB DIY'!S64) -> 58605.18 | L28: =('PDRB DIY'!T42+'PDRB DIY'!T50+'PDRB DIY'!T53+'PDRB DIY'!T57+'PDRB DIY'!T59+'PDRB DIY'!T60+'PDRB DIY'!T62+'PDRB DIY'!T63+'PDRB DIY'!T64) -> 61660.87 | ... O28: =('PDRB DIY'!W42+'PDRB DIY'!W50+'PDRB DIY'!W53+'PDRB DIY'!W57+'PDRB DIY'!W59+'PDRB DIY'!W60+'PDRB DIY'!W62+'PDRB DIY'!W63+'PDRB DIY'!W64) -> 71999.6 | P28: BPS Provinsi DIY | Q28: https://yogyakarta.bps.go.id/id/statistics-table/3/VWtsTFNuRlpabk16TWxKaVNXcE1PRXhKT0RJclFUMDkjMyMzNDAw/produk-domestik-regional-bruto-atas-dasar-harga-konstan-2010-menurut-lapangan-usaha-di-provinsi-di-yogyakarta--miliar-rupiah-.html?year=2025
A29: 16 | B29: Total Malam Menginap | C29: Aux | D29: Malam | E29: =E64 -> 5698325 | F29: =F64 -> 6097324 | G29: =G64 -> 10899900 | H29: =H64 -> 10293319 | I29: =I64 -> 13363923 | J29: =J64 -> 4753098 | K29: =K64 -> 7379577 | L29: =L64 -> 9267217 | ... O29: =O64 -> 11954114 | P29: Publikasi Tingkat Penghunian Kamar | Q29: https://yogyakarta.bps.go.id/id/publication/2026/07/27/3fead412fd5e3b779ba60710/tingkat-penghunian-kamar-hotel-daerah-istimewa-yogyakarta-2025.html
A30: 17 | B30: Pengeluaran Wisatawan | C30: Aux | D30: Miliar Rupiah | E30: =E2*E43 -> 6566.0528 | F30: =F2*F43 -> 7395.3944 | G30: =G2*G43 -> 8270.4986 | H30: =H2*H43 -> 10975.919 | I30: =I2*I43 -> 25567.652 | J30: =J2*J43 -> 24683.598 | K30: =K2*K43 -> 46504.796 | L30: =L2*L43 -> 51768.493 | ... O30: =O2*O43 -> 110700.68 | P30: Diolah
B31: Pengeluaran per Perjalanan Wisatawan Nusantara | C31: Data pendukung | D31: Ribu Rupiah | H31: 1084.61 | I31: 1163.4 | J31: 1230.84 | K31: 2006.76 | L31: 2000.45 | M31: 2351.86 | N31: 2666.17 | O31: 2672.98 | P31: Publikasi Statistik Wisatawan Nusantara | Q31: https://www.bps.go.id/id/publication/2026/04/30/06948320ebe75b7678b09c56/statistik-wisatawan-nusantara-2025.html
A33: 18 | B33: Tingkat Penghunian Kamar (TPK) | C33: Aux | D33: Persen | E33: 34.89 | F33: 37.72 | G33: 45.08 | H33: 45.11 | I33: 45.34 | J33: 28.9 | K33: 27.48 | L33: 44.99 | M33: 44.77 | N33: 42.17 | O33: 38.07 | P33: Publikasi Tingkat Penghunian Kamar, BPS | Q33: https://yogyakarta.bps.go.id/id/publication/2026/07/27/3fead412fd5e3b779ba60710/tingkat-penghunian-kamar-hotel-daerah-istimewa-yogyakarta-2025.html | R33: Di model dibatasi maksimum 1 sesuai definisi BPS; permintaan di atas kapasitas ditampung variabel Rasio Permintaan terhadap Kapasitas Kamar. Di model dihitung sebagai MIN(1, Rasio Permintaan terhadap Kapasitas Kamar) sesuai definisi BPS, sehingga tidak dapat melebihi 100%. Sejak perbaikan uji kondisi ekstrem, TPK tidak lagi menjadi masukan bagi laju konstruksi akomodasi, melainkan berfungsi sebagai variabel indikator dan pembanding data pada uji perilaku. Sinyal pembangunan akomodasi diwakili Rasio Permintaan terhadap Kapasitas Kamar.
A34: 19 | B34: Investasi Sektor Pariwisata | C34: Aux | D34: Miliar Rupiah | E34: =('PMA+PMDA'!B51+'PMA+PMDA'!B52+'PMA+PMDA'!B71+'PMA+PMDA'!B79+'PMA+PMDA'!B80+'PMA+PMDA'!B81+'PMA+PMDA'!B84)/1000 -> 53.0896 | F34: =('PMA+PMDA'!C51+'PMA+PMDA'!C52+'PMA+PMDA'!C71+'PMA+PMDA'!C79+'PMA+PMDA'!C80+'PMA+PMDA'!C81+'PMA+PMDA'!C84)/1000 -> 373.8424 | G34: =('PMA+PMDA'!D51+'PMA+PMDA'!D52+'PMA+PMDA'!D71+'PMA+PMDA'!D79+'PMA+PMDA'!D80+'PMA+PMDA'!D81+'PMA+PMDA'!D84)/1000 -> 165.3915 | H34: =('PMA+PMDA'!E51+'PMA+PMDA'!E52+'PMA+PMDA'!E71+'PMA+PMDA'!E79+'PMA+PMDA'!E80+'PMA+PMDA'!E81+'PMA+PMDA'!E84)/1000 -> 568.3341 | I34: =('PMA+PMDA'!F51+'PMA+PMDA'!F52+'PMA+PMDA'!F71+'PMA+PMDA'!F79+'PMA+PMDA'!F80+'PMA+PMDA'!F81+'PMA+PMDA'!F84)/1000 -> 741.4483 | J34: =('PMA+PMDA'!G51+'PMA+PMDA'!G52+'PMA+PMDA'!G71+'PMA+PMDA'!G79+'PMA+PMDA'!G80+'PMA+PMDA'!G81+'PMA+PMDA'!G84)/1000 -> 489.6932 | K34: =('PMA+PMDA'!H51+'PMA+PMDA'!H52+'PMA+PMDA'!H71+'PMA+PMDA'!H79+'PMA+PMDA'!H80+'PMA+PMDA'!H81+'PMA+PMDA'!H84)/1000 -> 848.8042 | L34: =('PMA+PMDA'!I51+'PMA+PMDA'!I52+'PMA+PMDA'!I71+'PMA+PMDA'!I79+'PMA+PMDA'!I80+'PMA+PMDA'!I81+'PMA+PMDA'!I84)/1000 -> 463.5886 | ... O34: =('PMA+PMDA'!L51+'PMA+PMDA'!L52+'PMA+PMDA'!L71+'PMA+PMDA'!L79+'PMA+PMDA'!L80+'PMA+PMDA'!L81+'PMA+PMDA'!L84)/1000 -> 1325.9504 | P34: BKPM | Q34: https://data.bkpm.go.id/visualisasi-detail/perkembangan-realisasi-investasi-oLSgf7G
A35: 20 | B35: Daya Tarik Destinasi Wisata | C35: Aux | D35: Dmnl | E35: =$O$55*(E8/$O$58)^$O$75+$O$56*($O$59/E36)+$O$57*(E37/$O$60) -> 2.8592249 | F35: =$O$55*(F8/$O$58)^$O$75+$O$56*($O$59/F36)+$O$57*(F37/$O$60) -> 2.8062693 | G35: =$O$55*(G8/$O$58)^$O$75+$O$56*($O$59/G36)+$O$57*(G37/$O$60) -> 2.7793291 | H35: =$O$55*(H8/$O$58)^$O$75+$O$56*($O$59/H36)+$O$57*(H37/$O$60) -> 2.4146189 | I35: =$O$55*(I8/$O$58)^$O$75+$O$56*($O$59/I36)+$O$57*(I37/$O$60) -> 1.3287407 | J35: =$O$55*(J8/$O$58)^$O$75+$O$56*($O$59/J36)+$O$57*(J37/$O$60) -> 1.3595552 | K35: =$O$55*(K8/$O$58)^$O$75+$O$56*($O$59/K36)+$O$57*(K37/$O$60) -> 1.2491241 | L35: =$O$55*(L8/$O$58)^$O$75+$O$56*($O$59/L36)+$O$57*(L37/$O$60) -> 1.1893638 | ... O35: =$O$55*(O8/$O$58)^$O$75+$O$56*($O$59/O36)+$O$57*(O37/$O$60) -> 1 | P35: Diolah dari rumus model: Jumlah ODTW, Kepadatan Wisatawan, Rasio Daya Dukung Lahan, bobot, dan nilai referensi 2025 | R35: Pengali efek terhadap laju kedatangan, bernilai 1 pada tahun dasar 2025 (Sterman, 2000). Indeks komposit linear tertimbang (OECD-JRC, 2008). Tidak ada data offstat; seri 2016–2024 hanya diagnostik. Nilai tinggi 2016–2018 disebabkan patahan metode data wisatawan. Keseimbangan jumlah wisatawan tercapai pada Daya Tarik = Laju Penurunan Dasar ÷ Laju Pertumbuhan Eksternal ≈ 0,75. Komponen kepadatan dibatasi maksimum 1 (MIN) karena kepadatan lebih rendah dari tahun dasar tidak menaikkan daya tarik di atas kondisi normal. Pembatasan ini hanya aktif pada kondisi ekstrem; pada seluruh periode historis dan simulasi dasar, rasio kepadatan selalu di bawah 1.
A36: 21 | B36: Kepadatan Wisatawan | C36: Aux | D36: Kunjungan/Hektar | E36: =E2/$O$70 -> 20.230305 | F36: =F2/$O$70 -> 20.664196 | G36: =G2/$O$70 -> 20.95791 | H36: =H2/$O$70 -> 25.224135 | I36: =I2/$O$70 -> 64.724839 | J36: =J2/$O$70 -> 61.8546 | K36: =K2/$O$70 -> 72.071924 | L36: =L2/$O$70 -> 81.239121 | ... O36: =O2/$O$70 -> 128.36288 | P36: Diolah: Jumlah Wisatawan (BPS) ÷ Luas Lahan Tersedia (luas wilayah DIY, BPS) | R36: Intensitas kunjungan per hektar wilayah (indikator tourism density; McElroy & de Albuquerque, 1998). Luas wilayah saling meniadakan dalam rasio Kepadatan Referensi ÷ Kepadatan, sehingga pilihan luas tidak memengaruhi Daya Tarik. Lonjakan 2018–2019 akibat patahan metode data wisatawan nusantara BPS. Berperan sebagai faktor pembatas daya tarik, dengan efek dibatasi maksimum pada kondisi tahun dasar.
A37: 22 | B37: Rasio Daya Dukung Lahan | C37: Aux | D37: dmnl | E37: =1-(E15/$O$70) -> 0.86425199 | F37: =1-(F15/$O$70) -> 0.85944474 | G37: =1-(G15/$O$70) -> 0.84158279 | H37: =1-(H15/$O$70) -> 0.82139454 | I37: =1-(I15/$O$70) -> 0.79977023 | J37: =1-(J15/$O$70) -> 0.81402099 | K37: =1-(K15/$O$70) -> 0.81110181 | L37: =1-(L15/$O$70) -> 0.81797311 | ... O37: =1-(O15/$O$70) -> 0.82642496 | R37: Nilai 2015 merupakan turunan ekstrapolasi Lahan Terbangun, model dibatasi minimum nol.
A38: 23 | B38: Intensitas Tenaga Kerja | C38: Aux | D38: Jiwa/Miliar Rupiah | E38: =$O$50*EXP(-$O$76*(VALUE(E$1)-2025)) -> 24.045763 | F38: =$O$50*EXP(-$O$76*(VALUE(F$1)-2025)) -> 23.782221 | G38: =$O$50*EXP(-$O$76*(VALUE(G$1)-2025)) -> 23.521567 | H38: =$O$50*EXP(-$O$76*(VALUE(H$1)-2025)) -> 23.26377 | I38: =$O$50*EXP(-$O$76*(VALUE(I$1)-2025)) -> 23.008798 | J38: =$O$50*EXP(-$O$76*(VALUE(J$1)-2025)) -> 22.756621 | K38: =$O$50*EXP(-$O$76*(VALUE(K$1)-2025)) -> 22.507208 | L38: =$O$50*EXP(-$O$76*(VALUE(L$1)-2025)) -> 22.260529 | ... O38: =$O$50*EXP(-$O$76*(VALUE(O$1)-2025)) -> 21.536593 | P38: Diolah dari rumus model: Intensitas Tenaga Kerja Awal × EXP(−Laju Kenaikan Produktivitas × (tahun − 2025)) | R38: Jumlah pekerja per miliar rupiah PDRB riil; kebalikan produktivitas tenaga kerja (OECD, 2001; ILO KILM). Menurun karena kenaikan produktivitas. Seri 2015–2024 adalah nilai rumus model yang dihitung mundur, untuk dibandingkan dengan rasio aktual TK ÷ PDRB (25,12 di 2015; 21,54 di 2025).
A39: 24 | B39: Tenaga Kerja Dibutuhkan | C39: Aux | D39: Jiwa | E39: =E27*E38 -> 243609.79 | F39: =F27*F38 -> 254327.78 | G39: =G27*G38 -> 266913.1 | H39: =H27*H38 -> 281514.65 | I39: =I27*I38 -> 301516.04 | J39: =J27*J38 -> 248657.73 | K39: =K27*K38 -> 272273.97 | L39: =L27*L38 -> 304358.86 | ... O39: =O27*O38 -> 364994 | P39: Diolah dari rumus model: PDRB ADHK Pariwisata × Intensitas Tenaga Kerja | R39: Jumlah pekerja yang dibutuhkan untuk menghasilkan PDRB pariwisata pada tingkat produktivitas tahun berjalan; permintaan tenaga kerja sebagai permintaan turunan dari output (Hamermesh, 1993). Nilai 2025 sama dengan tenaga kerja aktual karena Intensitas Awal diturunkan dari data 2025. Seri 2015–2024 dapat dibandingkan dengan Tenaga Kerja aktual (baris 13) sebagai cek kewajaran.
A40: 25 | B40: Rasio Permintaan terhadap Kapasitas Kamar | C40: Aux | D40: Dmnl | E40: =(E29/E63)/(E66*$O$68) -> 0.38909727 | F40: =(F29/F63)/(F66*$O$68) -> 0.37194264 | G40: =(G29/G63)/(G66*$O$68) -> 0.66291115 | H40: =(H29/H63)/(H66*$O$68) -> 0.4931533 | I40: =(I29/I63)/(I66*$O$68) -> 0.56296052 | J40: =(J29/J63)/(J66*$O$68) -> 0.19315884 | K40: =(K29/K63)/(K66*$O$68) -> 0.30337631 | L40: =(L29/L63)/(L66*$O$68) -> 0.36953318 | ... O40: =(O29/O63)/(O66*$O$68) -> 0.35771464 | P40: Diolah dari Total Malam Menginap, Tingkat Penghunian Ganda, dan Jumlah Kamar (BPS) | R40: Perbandingan permintaan terhadap kapasitas malam kamar. Historis selalu < 1, sehingga nilainya sama dengan TPK. Nilai > 1 hanya mungkin pada kondisi ekstrem dan menjadi sinyal pembangunan akomodasi.
A41: 26 | B41: Rata-rata lama menginap tamu | C41: Parameter | D41: Malam/Orang | E41: 1.4 | F41: 1.38 | G41: 1.59 | H41: 1.58 | I41: 1.48 | J41: 1.48 | K41: 1.59 | L41: 1.46 | M41: 1.45 | N41: 1.41 | O41: 1.43 | P41: Publikasi Tingkat Penghunian Kamar | Q41: https://yogyakarta.bps.go.id/id/publication/2026/07/27/3fead412fd5e3b779ba60710/tingkat-penghunian-kamar-hotel-daerah-istimewa-yogyakarta-2025.html
A42: 27 | B42: Laju Pertumbuhan Eksternal (Wisatawan) | C42: Parameter | D42: 1/Tahun | O42: =((O2/N2)-1)/(1-0.75) -> 0.26864027 | P42: Data Diolah | R42: seberapa besar potensi permintaan baru tiap tahun, dipengaruhi tren pariwisata di luar kendali DIY. g = pertumbuhan 2024–2025, karena data sebelum 2019 terpengaruh perubahan metode dan 2020–2024 merupakan masa pemulihan pandemi; sebanding dengan target Renstra Kemenpar (6,6–8,0% per tahun). Rasio Laju Penurunan Dasar ÷ Laju Pertumbuhan Eksternal = 0,75 merupakan asumsi struktural; diuji sensitivitas 0,6 dan 0,9.
...

Sheet PMA+PMDA
A1: KBLI 2 Digit | B1: 2015 | C1: 2016 | D1: 2017 | E1: 2018 | F1: 2019 | G1: 2020 | H1: 2021 | I1: 2022 | J1: 2023 | K1: 2024 | L1: 2025 | M1: Grand Total
A2: 00 - Bidang Usaha Lainnya | D2: 5360 | F2: 0
A3: 01 - Pertanian Tanaman, Peternakan, Perburuan Dan Kegiatan Ybdi | B3: 0 | C3: 0 | D3: 0 | E3: 1645 | F3: 0 | G3: 395.1 | H3: 223490.7 | I3: 34410.1 | J3: 22222.3 | K3: 35142 | L3: 71811.823
A4: 02 - Pengelolaan Kehutanan Dan Penebangan | G4: 0 | H4: 0 | I4: 0 | J4: 0 | K4: 136.3 | L4: 68.101108
A5: 03 - Perikanan | B5: 11037.2 | C5: 1904 | D5: 52.5 | E5: 327.4 | F5: 0 | I5: 0 | J5: 116.1 | K5: 355.8 | L5: 856.6
A6: 05 - Pertambangan Batu Bara Dan Lignit | J6: 0 | K6: 0 | L6: 0
A7: 06 - Pertambangan Minyak Bumi Dan Gas Alam Dan Panas Bumi | J7: 0 | K7: 0 | L7: 0
A8: 07 - Pertambangan Bijih Logam | B8: 119819.1 | C8: 29161.9 | D8: 53086.6 | E8: 43687.6 | F8: 8965.2 | G8: 20138.4 | H8: 4989.8 | I8: 4218.8 | J8: 2182.1 | K8: 557.5 | L8: 2981.7119
A9: 08 - Pertambangan Dan Penggalian Lainnya | F9: 1093.2 | G9: 315.7 | H9: 0 | I9: 13296.1 | J9: 5599.1 | K9: 151.8 | L9: 3097.997
A10: 09 - Aktivitas Jasa Penunjang Pertambangan | F10: 463.3 | G10: 215.9 | H10: 202.5 | I10: 0 | J10: 625.7 | K10: 1409.6 | L10: 11592.696
A11: 10 - Industri Makanan | B11: 32070.4 | C11: 17932.1 | D11: 13532.5 | E11: 2389.9 | F11: 1258.1 | G11: 15375.3 | H11: 32111.9 | I11: 150127.6 | J11: 74949.5 | K11: 143242.3 | L11: 113209.18
A12: 11 - Industri Minuman | D12: 996.7 | E12: 482.4 | G12: 154 | H12: 954.7 | I12: 1.8 | J12: 2830.8 | K12: 2672.5 | L12: 1867.9128
A13: 12 - Industri Pengolahan Tembakau | D13: 0 | E13: 0 | F13: 85.8 | G13: 11.7 | H13: 1288.3 | I13: 18208.7 | J13: 1560.4 | K13: 2408.4 | L13: 10234.662
A14: 13 - Industri Tekstil | B14: 27625.9 | D14: 0 | E14: 12046.2 | F14: 5433.7 | G14: 94981.6 | H14: 23878 | I14: 47499.3 | J14: 54790.1 | K14: 54228.7 | L14: 122213.74
A15: 14 - Industri Pakaian Jadi | B15: 41824.1 | C15: 74829.4 | D15: 68769.2 | E15: 41027.5 | F15: 47812.8 | G15: 5165.7 | H15: 41910.7 | I15: 215995.4 | J15: 81890.4 | K15: 534484.5 | L15: 117331.53
A16: 15 - Industri Kulit, Barang Dari Kulit Dan Alas Kaki | B16: 22483.8 | C16: 10751.6 | D16: 15041 | E16: 21787 | F16: 30483.5 | G16: 10774.9 | H16: 20058.3 | I16: 8404 | J16: 35909.3 | K16: 58952.2 | L16: 27593.359
A17: 16 - Industri Kayu, Barang Dari Kayu Dan Gabus (Tidak Termasuk Furnitur) Dan Barang Anyaman Dari Bambu, Rotan Dan Sejenisnya | B17: 0 | C17: 224.5 | D17: 18 | E17: 224.1 | F17: 27647.2 | G17: 1078.3 | H17: 3100.6 | I17: 1397.6 | J17: 19658.9 | K17: 6082 | L17: 7308.2733
A18: 17 - Industri Kertas Dan Barang Dari Kertas | B18: 25146.4 | C18: 29766.8 | D18: 14927.6 | E18: 1452.5 | F18: 431.6 | G18: 1599.6 | H18: 2120.5 | I18: 3316.1 | J18: 94041.2 | K18: 12331.3 | L18: 200867.04
A19: 18 - Industri Pencetakan Dan Reproduksi Media Rekaman | E19: 360 | F19: 0 | G19: 95 | H19: 382.7 | I19: 7339.7 | J19: 13008 | K19: 12964.5 | L19: 10663.593
A20: 19 - Industri Produk Dari Batu Bara Dan Pengilangan Minyak Bumi | E20: 1670 | F20: 200 | G20: 80 | H20: 3480 | I20: 1000 | J20: 521 | K20: 4006.3 | L20: 616.5
A21: 20 - Industri Bahan Kimia Dan Barang Dari Bahan Kimia | B21: 1521.6 | C21: 6402.5 | D21: 59220.6 | E21: 7176 | F21: 12026.7 | G21: 21338.9 | H21: 38021.5 | I21: 22267.8 | J21: 14454 | K21: 2504.3 | L21: 10706.994
A22: 21 - Industri Farmasi, Produk Obat Kimia Dan Obat Tradisional | C22: 14849.9 | D22: 0 | E22: 19773 | F22: 1635.5 | G22: 5806.5 | H22: 3135.4 | I22: 15676.8 | J22: 11780.1 | K22: 8491.3 | L22: 10364.149
A23: 22 - Industri Karet, Barang Dari Karet Dan Plastik | D23: 6911.8 | E23: 869.7 | F23: 3460.9 | G23: 4698.1 | H23: 2032.7 | I23: 3783.3 | J23: 1141.5 | K23: 6441.9 | L23: 2440.6881
A24: 23 - Industri Barang Galian Bukan Logam | B24: 7865.1 | C24: 112 | D24: 16131.4 | E24: 14027.7 | F24: 32374.4 | G24: 2124.3 | H24: 71.9 | I24: 10135.7 | J24: 55429.4 | K24: 7997.4 | L24: 21092.803
A25: 24 - Industri Logam Dasar | G25: 0 | H25: 34.2 | I25: 0 | J25: 472.7 | K25: 0 | L25: 0
A26: 25 - Industri Barang Logam, Bukan Mesin Dan Peralatannya | C26: 18856.8 | D26: 18400 | E26: 16735.5 | F26: 6779.3 | G26: 143.7 | H26: 4199.4 | I26: 21368.6 | J26: 1125.4 | K26: 11829.3 | L26: 13585.171
A27: 26 - Industri Komputer, Barang Elektronik Dan Optik | G27: 0 | H27: 0 | I27: 1022.9 | J27: 393.2 | K27: 2525.2 | L27: 2511.4487
A28: 27 - Industri Peralatan Listrik | B28: 0 | C28: 0 | D28: 0 | G28: 0 | H28: 0 | J28: 0 | K28: 860 | L28: 1541.2829
A29: 28 - Industri Mesin Dan Perlengkapan Ytdl | B29: 115341.6 | C29: 171.3 | D29: 151.1 | E29: 8211.5 | F29: 66 | G29: 59.9 | H29: 0 | I29: 2259.1 | J29: 1672.7 | K29: 3104.2 | L29: 3487.4443
A30: 29 - Industri Kendaraan Bermotor, Trailer Dan Semi Trailer | D30: 28745.7 | E30: 70997.7 | F30: 0 | H30: 9653.6 | J30: 0 | K30: 13155.8 | L30: 123.9
A31: 30 - Industri Alat Angkutan Lainnya | I31: 0 | J31: 0 | K31: 0 | L31: 4373.75
A32: 31 - Industri Furnitur | B32: 6248 | C32: 18225.4 | D32: 10451.8 | E32: 2291.4 | F32: 494.9 | G32: 4810.5 | H32: 6606.5 | I32: 19314.7 | J32: 12432 | K32: 2768.9 | L32: 18317.305
A33: 32 - Industri Pengolahan Lainnya | B33: 636.9 | C33: 1665.8 | D33: 14967.5 | E33: 19574.3 | F33: 135607.7 | G33: 13201 | H33: 6091.1 | I33: 45590.9 | J33: 118030.7 | K33: 33295.7 | L33: 365078.8
A34: 33 - Reparasi Dan Pemasangan Mesin Dan Peralatan | F34: 0 | G34: 80 | H34: 0 | I34: 0 | J34: 52.5 | K34: 0 | L34: 1175.6976
A35: 35 - Pengadaan Listrik, Gas, Uap/Air Panas Dan Udara Dingin | B35: 30762.5 | C35: 13253.5 | D35: 16996.9 | E35: 959.7 | F35: 1603.4 | G35: 59250.4 | H35: 6557.6 | I35: 0 | J35: 1906.2 | K35: 29664.3 | L35: 44303.416
A36: 36 - Treatment Air | F36: 1738.7 | G36: 0 | H36: 0 | I36: 1740.6 | J36: 0 | K36: 4793 | L36: 3401.4751
A37: 37 - Treatment Air Limbah | B37: 1136.4 | C37: 179.8 | D37: 268.8 | E37: 32.8 | F37: 368.2 | G37: 28.5 | H37: 0 | I37: 0 | J37: 0 | K37: 4.2 | L37: 13.539244
A38: 38 - Pengumpulan, Treatment Dan Pembuangan Limbah Dan Sampah Serta Aktivitas Pemulihan Material | D38: 0 | E38: 0 | F38: 0 | G38: 0 | H38: 310 | I38: 184 | J38: 0 | K38: 13696.1 | L38: 229.08924
A39: 39 - Aktivitas Remediasi Dan Pengelolaan Limbah Dan Sampah Lainnya | G39: 0 | I39: 0 | J39: 0 | K39: 0 | L39: 212.2429
A40: 41 - Konstruksi Gedung | B40: 0 | D40: 0 | E40: 4400450 | F40: 3165458 | G40: 106604 | H40: 956.1 | I40: 8937.3 | J40: 35107 | K40: 20588.5 | L40: 25176.287
...

Sheet PDRB DIY
A1: 52 Kategori PDRB Lapus | B1: [Seri 2010] Produk Domestik Regional Bruto Menurut Lapangan Usaha Tahunan (Miliar Rupiah) Provinsi Daerah Istimewa Yogyakarta
B2: Harga Berlaku | M2: Harga Konstan 2010
B3: 2015 | C3: 2016 | D3: 2017 | E3: 2018 | F3: 2019 | G3: 2020 | H3: 2021 | I3: 2022 | J3: 2023 | K3: 2024 | L3: 2025 | M3: 2015 | N3: 2016 | O3: 2017 | P3: 2018 | Q3: 2019 | R3: 2020 | S3: 2021 | T3: 2022 | U3: 2023 | V3: 2024 | W3: 2025
A4: A. Pertanian, Kehutanan, dan Perikanan | B4: 10793.84 | C4: 11456.17 | D4: 11932.98 | E4: 12700.21 | F4: 13237.38 | G4: 14056.68 | H4: 14601.86 | I4: 16525.78 | J4: 18488.33 | K4: 19200.89 | L4: 21082.58 | M4: 7667.6 | N4: 7779.8 | O4: 7930.31 | P4: 8101.23 | Q4: 8184.19 | R4: 8534.64 | S4: 8638.19 | T4: 9077.78 | U4: 9169.84 | V4: 9177.04 | W4: 9791.83
A5: 1. Pertanian, Peternakan, Perburuan dan Jasa Pertanian | B5: 9442.59 | C5: 10036.12 | D5: 10423.67 | E5: 11149.34 | F5: 11639.23 | G5: 12556.03 | H5: 12981.69 | I5: 14948.09 | J5: 16887.62 | K5: 17582.29 | L5: 19393.54 | M5: 6666.7 | N5: 6766.49 | O5: 6883.68 | P5: 7069.78 | Q5: 7170.24 | R5: 7621.61 | S5: 7707.93 | T5: 8223.21 | U5: 8347.25 | V5: 8375.4 | W5: 8973.43
A6: a. Tanaman Pangan | B6: 3808.41 | C6: 4134.84 | D6: 4232.04 | E6: 4564.74 | F6: 4653.22 | G6: 5182.29 | H6: 5068.94 | I6: 5892.29 | J6: 7058.31 | K6: 7020.71 | L6: 8326.94 | M6: 2838.36 | N6: 2916.63 | O6: 2895.31 | P6: 2950.95 | Q6: 2940.43 | R6: 3235.4 | S6: 3130.92 | T6: 3302.44 | U6: 3263.96 | V6: 3090.85 | W6: 3590.96
A7: b. Tanaman Hortikultura | B7: 3023.44 | C7: 3114.05 | D7: 3268.74 | E7: 3431.11 | F7: 3685.41 | G7: 3958.91 | H7: 4220.43 | I7: 4953.87 | J7: 5324.03 | K7: 5711.69 | L7: 5895.21 | M7: 1929.98 | N7: 1913.55 | O7: 1974.73 | P7: 2021.18 | Q7: 2084.24 | R7: 2209.32 | S7: 2296.18 | T7: 2531.73 | U7: 2593.41 | V7: 2696.23 | W7: 2686.9
A8: c. Tanaman Perkebunan | B8: 278.97 | C8: 309.81 | D8: 332.6 | E8: 349.48 | F8: 369.21 | G8: 402.88 | H8: 343.37 | I8: 391.77 | J8: 468.06 | K8: 537.96 | L8: 596.25 | M8: 201.22 | N8: 201.49 | O8: 210.22 | P8: 218.35 | Q8: 232.06 | R8: 251.74 | S8: 218.55 | T8: 228.95 | U8: 234.16 | V8: 250.97 | W8: 260.65
A9: d. Peternakan | B9: 2136.76 | C9: 2265.24 | D9: 2359.15 | E9: 2561.09 | F9: 2682.25 | G9: 2771.71 | H9: 3088.92 | I9: 3424.81 | J9: 3727.39 | K9: 3982.62 | L9: 4225.54 | M9: 1548.21 | N9: 1581.6 | O9: 1643.59 | P9: 1715.41 | Q9: 1749.02 | R9: 1770.22 | S9: 1900.97 | T9: 1994.02 | U9: 2086.75 | V9: 2169.42 | W9: 2262.93
A10: e. Jasa Pertanian dan Perburuan | B10: 195 | C10: 212.18 | D10: 231.14 | E10: 242.91 | F10: 249.14 | G10: 240.23 | H10: 260.03 | I10: 285.35 | J10: 309.82 | K10: 329.32 | L10: 349.59 | M10: 148.93 | N10: 153.22 | O10: 159.83 | P10: 163.88 | Q10: 163.99 | R10: 154.92 | S10: 161.31 | T10: 166.06 | U10: 168.98 | V10: 167.92 | W10: 171.99
A11: 2. Kehutanan dan Penebangan | B11: 902.9 | C11: 955.19 | D11: 1004.94 | E11: 1020.26 | F11: 1086.97 | G11: 952.69 | H11: 1008.62 | I11: 899.6 | J11: 919.71 | K11: 921.13 | L11: 931.74 | M11: 700.24 | N11: 708.45 | O11: 728.83 | P11: 711.11 | Q11: 712.44 | R11: 594.6 | S11: 584.39 | T11: 487.41 | U11: 473.38 | V11: 449.97 | W11: 450.74
A12: 3. Perikanan | B12: 448.35 | C12: 464.87 | D12: 504.37 | E12: 530.61 | F12: 511.19 | G12: 547.96 | H12: 611.55 | I12: 678.09 | J12: 681.01 | K12: 697.47 | L12: 757.3 | M12: 300.66 | N12: 304.86 | O12: 317.81 | P12: 320.35 | Q12: 301.5 | R12: 318.43 | S12: 345.87 | T12: 367.17 | U12: 349.2 | V12: 351.67 | W12: 367.66
A13: B. Pertambangan dan Penggalian | B13: 573.13 | C13: 593.16 | D13: 615.94 | E13: 680.66 | F13: 713.92 | G13: 657 | H13: 664.74 | I13: 713.77 | J13: 799.92 | K13: 869.77 | L13: 791.27 | M13: 471.32 | N13: 473.3 | O13: 489.35 | P13: 541.18 | Q13: 557.65 | R13: 508.38 | S13: 492.58 | T13: 501.03 | U13: 517.33 | V13: 556.4 | W13: 591.97
A14: 1. Pertambangan Minyak, Gas dan Panas Bumi | B14: - | C14: - | D14: - | E14: - | F14: - | G14: - | H14: - | I14: - | J14: - | K14: - | L14: - | M14: - | N14: - | O14: - | P14: - | Q14: - | R14: - | S14: - | T14: - | U14: - | V14: - | W14: -
A15: 2. Pertambangan Batu Bara dan Lignit | B15: - | C15: - | D15: - | E15: - | F15: - | G15: - | H15: - | I15: - | J15: - | K15: - | L15: - | M15: - | N15: - | O15: - | P15: - | Q15: - | R15: - | S15: - | T15: - | U15: - | V15: - | W15: -
A16: 3. Pertambangan Bijih Logam | B16: - | C16: - | D16: - | E16: - | F16: - | G16: - | H16: - | I16: - | J16: - | K16: - | L16: - | M16: - | N16: - | O16: - | P16: - | Q16: - | R16: - | S16: - | T16: - | U16: - | V16: - | W16: -
A17: 4. Pertambangan dan Penggalian Lainnya | B17: 573.13 | C17: 593.16 | D17: 615.94 | E17: 680.66 | F17: 713.92 | G17: 657 | H17: 664.74 | I17: 713.77 | J17: 799.92 | K17: 869.77 | L17: 791.27 | M17: 471.32 | N17: 473.3 | O17: 489.35 | P17: 541.18 | Q17: 557.65 | R17: 508.38 | S17: 492.58 | T17: 501.03 | U17: 517.33 | V17: 556.4 | W17: 591.97
A18: C. Industri Pengolahan | B18: 13303.47 | C18: 14547.35 | D18: 15635.87 | E18: 16870 | F18: 18085.08 | G18: 17643.51 | H18: 18448.61 | I18: 19775.46 | J18: 21353.1 | K18: 22894.26 | L18: 24552.34 | M18: 10693.04 | N18: 11234.47 | O18: 11878.96 | P18: 12486.86 | Q18: 13200.73 | R18: 12632.11 | S18: 12670.46 | T18: 12890.39 | U18: 13442.25 | V18: 13929.58 | W18: 14559.81
A19: 1. Industri Batubara dan Pengilangan Migas | B19: - | C19: - | D19: - | E19: - | F19: - | G19: - | H19: - | I19: - | J19: - | K19: - | L19: - | M19: - | N19: - | O19: - | P19: - | Q19: - | R19: - | S19: - | T19: - | U19: - | V19: - | W19: -
A20: 2. Industri Makanan dan Minuman | B20: 7103.6 | C20: 7941.76 | D20: 8558.24 | E20: 9390.16 | F20: 10226.78 | G20: 9931.58 | H20: 10048.92 | I20: 10780.45 | J20: 11683.26 | K20: 12719.38 | L20: 14028.33 | M20: 5724.93 | N20: 6111.91 | O20: 6505.52 | P20: 6954.98 | Q20: 7508.5 | R20: 7163.56 | S20: 6966.04 | T20: 7052.86 | U20: 7392.38 | V20: 7740.44 | W20: 8270.19
A21: 3. Industri Pengolahan Tembakau | B21: 742.3 | C21: 794.42 | D21: 910.08 | E21: 981.95 | F21: 1030.85 | G21: 1140.35 | H21: 1338.17 | I21: 1427.53 | J21: 1523.37 | K21: 1599.87 | L21: 1631.9 | M21: 453.23 | N21: 460.06 | O21: 489.34 | P21: 514.94 | Q21: 523.8 | R21: 567.98 | S21: 631.43 | T21: 645.79 | U21: 686.35 | V21: 685.62 | W21: 671.72
A22: 4. Industri Tekstil dan Pakaian Jadi | B22: 1458.64 | C22: 1602.09 | D22: 1736.48 | E22: 1892.26 | F22: 2059.93 | G22: 2030.79 | H22: 2310.72 | I22: 2448.69 | J22: 2636.03 | K22: 2808.2 | L22: 2948.34 | M22: 1122.11 | N22: 1193.57 | O22: 1274.08 | P22: 1348.91 | Q22: 1439.85 | R22: 1379.24 | S22: 1494.4 | T22: 1521.63 | U22: 1573.95 | V22: 1631.76 | W22: 1689.4
A23: 5. Industri Kulit, Barang dari Kulit dan Alas Kaki | B23: 378.49 | C23: 404.32 | D23: 430.5 | E23: 421.22 | F23: 426.01 | G23: 357.51 | H23: 365.45 | I23: 404.68 | J23: 433.47 | K23: 449.66 | L23: 459.15 | M23: 300.27 | N23: 310.01 | O23: 323.93 | P23: 307.91 | Q23: 305.13 | R23: 252.67 | S23: 257.09 | T23: 273.19 | U23: 284.21 | V23: 290.53 | W23: 292.21
A24: 6. Industri Kayu, Barang dari Kayu dan Gabus dan Barang Anyaman dari Bambu, Rotan dan Sejenisnya | B24: 204.4 | C24: 205.28 | D24: 225.3 | E24: 241.77 | F24: 244.92 | G24: 233.75 | H24: 228.82 | I24: 257.96 | J24: 267.65 | K24: 279.98 | L24: 280.59 | M24: 186.55 | N24: 183.51 | O24: 198.31 | P24: 209.43 | Q24: 209.62 | R24: 198.96 | S24: 187.17 | T24: 198.56 | U24: 199.67 | V24: 204.83 | W24: 196.68
A25: 7. Industri Kertas dan Barang dari Kertas, Percetakan dan Reproduksi Media Rekaman | B25: 293.84 | C25: 322.79 | D25: 346.84 | E25: 374.2 | F25: 405.21 | G25: 397.94 | H25: 389.76 | I25: 426.22 | J25: 489.48 | K25: 515.25 | L25: 498.01 | M25: 253.69 | N25: 268.71 | O25: 278.53 | P25: 287.37 | Q25: 307.56 | R25: 296.47 | S25: 283.78 | T25: 286.49 | U25: 311.91 | V25: 317.81 | W25: 309.93
A26: 8. Industri Kimia, Farmasi dan Obat Tradisional | B26: 131 | C26: 142.9 | D26: 152.56 | E26: 158.41 | F26: 164.06 | G26: 184.2 | H26: 191.75 | I26: 202.41 | J26: 202.46 | K26: 202.61 | L26: 209.92 | M26: 135.4 | N26: 144.38 | O26: 152.56 | P26: 154.83 | Q26: 157.74 | R26: 174.64 | S26: 175.13 | T26: 174.78 | U26: 166.88 | V26: 163.06 | W26: 164.67
A27: 9. Industri Karet, Barang dari Karet dan Plastik | B27: 318.02 | C27: 306.05 | D27: 310.26 | E27: 314.39 | F27: 319.98 | G27: 309.64 | H27: 331.78 | I27: 335.76 | J27: 338.02 | K27: 341.58 | L27: 346.82 | M27: 265.7 | N27: 246.69 | O27: 254.14 | P27: 253.46 | Q27: 256.77 | R27: 249.83 | S27: 268.04 | T27: 263 | U27: 258.7 | V27: 252.45 | W27: 251.66
A28: 10. Industri Barang Galian bukan Logam | B28: 426.57 | C28: 438.02 | D28: 472.98 | E28: 495.09 | F28: 494.99 | G28: 433.98 | H28: 463.92 | I28: 512.08 | J28: 565.33 | K28: 604.05 | L28: 602.36 | M28: 335.7 | N28: 336.59 | O28: 360.4 | P28: 373.12 | Q28: 369.07 | R28: 318.84 | S28: 332.93 | T28: 347.62 | U28: 367.35 | V28: 381.69 | W28: 370.65
A29: 11. Industri Logam Dasar | B29: - | C29: - | D29: - | E29: - | F29: - | G29: - | H29: - | I29: - | J29: - | K29: - | L29: - | M29: - | N29: - | O29: - | P29: - | Q29: - | R29: - | S29: - | T29: - | U29: - | V29: - | W29: -
A30: 12. Industri Barang Logam, Komputer, Barang Elektronik, Optik, dan Peralatan Listrik | B30: 890.73 | C30: 935.01 | D30: 938.7 | E30: 925.06 | F30: 958.73 | G30: 964.11 | H30: 1023.28 | I30: 1090.39 | J30: 1199.72 | K30: 1294.41 | L30: 1389.48 | M30: 777.41 | N30: 801.51 | O30: 799.6 | P30: 770.48 | Q30: 785.49 | R30: 792.35 | S30: 806.19 | T30: 824.26 | U30: 887.28 | V30: 941.6 | W30: 992.81
A31: 13. Industri Mesin dan Perlengkapan | B31: 494.96 | C31: 542.43 | D31: 562.13 | E31: 582.98 | F31: 592.63 | G31: 534 | H31: 545.67 | I31: 572.26 | J31: 622.73 | K31: 633.42 | L31: 665.74 | M31: 430.75 | N31: 450.7 | O31: 465.14 | P31: 476.24 | Q31: 471.57 | R31: 417.45 | S31: 411.9 | T31: 407.29 | U31: 410.04 | V31: 399.98 | W31: 416.06
A32: 14. Industri Alat Angkutan | B32: 3.1 | C32: 3.05 | D32: 3.19 | E32: 3.35 | F32: 3.53 | G32: 3.64 | H32: 3.24 | I32: 3.42 | J32: 3.75 | K32: 3.82 | L32: 3.98 | M32: 2.63 | N32: 2.51 | O32: 2.61 | P32: 2.7 | Q32: 2.77 | R32: 2.79 | S32: 2.43 | T32: 2.36 | U32: 2.4 | V32: 2.4 | W32: 2.5
A33: 15. Industri Furnitur | B33: 538.31 | C33: 572.73 | D33: 625.51 | E33: 692.14 | F33: 732.58 | G33: 721.59 | H33: 802.75 | I33: 868.17 | J33: 908.85 | K33: 931.47 | L33: 958.77 | M33: 453.94 | N33: 470.53 | O33: 503.68 | P33: 545.91 | Q33: 566.5 | R33: 542.97 | S33: 584.49 | T33: 609.41 | U33: 615.89 | V33: 622.95 | W33: 632.39
A34: 16. Industri Pengolahan Lainnya, Jasa Reparasi dan Pemasangan Mesin dan Peralatan | B34: 319.5 | C34: 336.49 | D34: 363.1 | E34: 397.04 | F34: 424.88 | G34: 400.42 | H34: 404.39 | I34: 445.45 | J34: 478.99 | K34: 510.55 | L34: 528.96 | M34: 250.7 | N34: 253.8 | O34: 271.12 | P34: 286.56 | Q34: 296.36 | R34: 274.36 | S34: 269.44 | T34: 283.13 | U34: 285.25 | V34: 294.45 | W34: 298.94
A35: D. Pengadaan Listrik dan Gas | B35: 118.01 | C35: 141.79 | D35: 173.69 | E35: 186.51 | F35: 202.28 | G35: 198.15 | H35: 203.05 | I35: 223.58 | J35: 250 | K35: 277.56 | L35: 292.22 | M35: 127.7 | N35: 145.91 | O35: 151.68 | P35: 156.71 | Q35: 165.22 | R35: 162.93 | S35: 166.85 | T35: 178.22 | U35: 191.26 | V35: 211.67 | W35: 221.32
A36: 1. Ketenagalistrikan | B36: 117.04 | C36: 140.75 | D36: 172.56 | E36: 185.38 | F36: 201.01 | G36: 196.99 | H36: 201.87 | I36: 222.23 | J36: 248.06 | K36: 274.04 | L36: 288.38 | M36: 126.89 | N36: 145.09 | O36: 150.84 | P36: 155.86 | Q36: 164.28 | R36: 162.07 | S36: 166 | T36: 177.29 | U36: 189.95 | V36: 209.3 | W36: 218.8
A37: 2. Pengadaan Gas dan Produksi Es | B37: 0.97 | C37: 1.05 | D37: 1.13 | E37: 1.14 | F37: 1.26 | G37: 1.16 | H37: 1.18 | I37: 1.35 | J37: 1.93 | K37: 3.52 | L37: 3.84 | M37: 0.81 | N37: 0.82 | O37: 0.84 | P37: 0.84 | Q37: 0.93 | R37: 0.85 | S37: 0.85 | T37: 0.93 | U37: 1.3 | V37: 2.38 | W37: 2.51
A38: E. Pengadaan Air, Pengelolaan Sampah, Limbah dan Daur Ulang | B38: 109.7 | C38: 114.76 | D38: 121.27 | E38: 128.13 | F38: 139.65 | G38: 141.44 | H38: 153.14 | I38: 162.57 | J38: 171.98 | K38: 174.22 | L38: 174.28 | M38: 85.26 | N38: 87.27 | O38: 90.29 | P38: 94.92 | Q38: 103.37 | R38: 103.9 | S38: 110.99 | T38: 114.64 | U38: 118.57 | V38: 119.62 | W38: 118.96
A39: F. Konstruksi | B39: 9499.92 | C39: 10286.73 | D39: 11310.87 | E39: 13351.68 | F39: 15717.53 | G39: 13325.55 | H39: 15147.86 | I39: 16440.15 | J39: 17037.27 | K39: 18640.92 | L39: 20420.61 | M39: 7826.7 | N39: 8250.61 | O39: 8828.65 | P39: 9984.76 | Q39: 11420.64 | R39: 9636.84 | S39: 10679.27 | T39: 11193.38 | U39: 11732.07 | V39: 12722.05 | W39: 13717.54
A40: G. Perdagangan Besar dan Eceran; Reparasi Mobil dan Sepeda Motor | B40: 8342.65 | C40: 9297.75 | D40: 10220.36 | E40: 11156.43 | F40: 11958.91 | G40: 11638.99 | H40: 12169.43 | I40: 13677.56 | J40: 14768.7 | K40: 15619.25 | L40: 16761.57 | M40: 6944.9 | N40: 7366.32 | O40: 7787.54 | P40: 8219.29 | Q40: 8643.44 | R40: 8254.03 | S40: 8379.07 | T40: 8779.73 | U40: 9159.47 | V40: 9519.98 | W40: 10024.25
...

Sheet Perhitungan faktor sambung
A1: Langkah 1 — Pertumbuhan sebelum patahan (2015–2018), memakai metode lama yang konsisten:
A2: g_pra = (Wisatawan 2018 ÷ Wisatawan 2015)^(1/3) − 1 | E2: =('Data Tahunan'!H2/'Data Tahunan'!E2)^(1/3) - 1 -> 0.07631143 | F2: 7.63% / tahun
A4: Langkah 2 — Pertumbuhan setelah patahan (2021–2025), memakai metode baru, dan sengaja dimulai 2021 supaya tahun COVID tidak ikut:
A5: g_pasca = (Wisatawan 2025 ÷ Wisatawan 2021)^(1/4) − 1 | E5: =('Data Tahunan'!O2/'Data Tahunan'!K2)^(1/4) - 1 -> 0.15522967 | F5: 15.52% / tahun
A7: Langkah 3 — Pertumbuhan wajar 2018→2019, diasumsikan rata-rata keduanya:
A8: g_wajar = (g_pra + g_pasca) ÷ 2 | E8: =(E2+E5)/2 -> 0.11577055 | F8: 11.58% / tahun
A10: Langkah 4 — Lompatan total:
A11: Wisatawan 2019 ÷ Wisatawan 2018 | E11: ='Data Tahunan'!I2/'Data Tahunan'!H2 -> 2.5659884 | F11: 2.566
A13: Langkah 5 — Faktor sambung:
A14: Faktor = Lompatan total/(1+g_wajar) | E14: =E11/(1+E8) -> 2.2997456 | F14: 2.2997
A16: Langkah 6 — Kalikan data 2015–2018:
A18: Tahun | B18: Data Asli | C18: Seri Sambungan | E18: pertumbuhan 2015–2018 = 7,63%
A19: 2015 | B19: ='Data Tahunan'!E2 -> 6413735 | C19: =B19*$E$14 -> 14749959 | E19: 2021–2025 = 15,52%
A20: 2016 | B20: ='Data Tahunan'!F2 -> 6551294 | C20: =B20*$E$14 -> 15066309 | E20: lompatan 2018→2019 = 156,6%
A21: 2017 | B21: ='Data Tahunan'!G2 -> 6644412 | C21: =B21*$E$14 -> 15280457 | E21: faktor = 2,2997
A22: 2018 | B22: ='Data Tahunan'!H2 -> 7996959 | C22: =B22*$E$14 -> 18390971
A23: 2019 | B23: ='Data Tahunan'!I2 -> 20520104
A24: 2020 | B24: ='Data Tahunan'!J2 -> 19610135
A25: 2021 | B25: ='Data Tahunan'!K2 -> 22849394
A26: 2022 | B26: ='Data Tahunan'!L2 -> 25755726
A27: 2023 | B27: ='Data Tahunan'!M2 -> 30542580
A28: 2024 | B28: ='Data Tahunan'!N2 -> 38134536
A29: 2025 | B29: ='Data Tahunan'!O2 -> 40695654

Sheet Data Historis
A1: Tahun | B1: Jumlah Wisatawan | C1: Jumlah Hotel dan Akomodasi | D1: Jumlah Objek Daya Tarik Wisata | E1: Tenaga Kerja Pariwisata | F1: Lahan Terbangun | G1: Tingkat Penghunian Kamar (TPK) | H1: PDRB Sektor Pariwisata | I1: Investasi Sektor Pariwisata | J1: Total Malam Menginap
A2: 2016 | B2: ='Perhitungan faktor sambung'!C20 -> 15066309 | C2: 1170 | D2: 158 | E2: 263878 | F2: 44561.078 | G2: 37.72 | H2: 10694.03 | I2: 373.8424 | J2: 6097324
A3: 2017 | B3: ='Perhitungan faktor sambung'!C21 -> 15280457 | C3: 1179 | D3: 171 | E3: =151687+121876 -> 273563 | F3: 50223.957 | G3: 45.08 | H3: 11347.59 | I3: 165.3915 | J3: 10899900
A4: 2018 | B4: ='Perhitungan faktor sambung'!C22 -> 18390971 | C4: 1617 | D4: 177 | E4: =143309+211375 -> 354684 | F4: 56624.36 | G4: 45.11 | H4: 12100.99 | I4: 568.3341 | J4: 10293319
A5: 2019 | B5: ='Data Tahunan'!I2 -> 20520104 | C5: 1817 | D5: 189 | E5: =130357+204427 -> 334784 | F5: 63480.044 | G5: 45.34 | H5: 13104.38 | I5: 741.4483 | J5: 13363923
A6: 2020 | B6: ='Data Tahunan'!J2 -> 19610135 | C6: 1848 | D6: 180 | E6: =138570+175270 -> 313840 | F6: 58962.041 | G6: 28.9 | H6: 10926.83 | I6: 489.6932 | J6: 4753098
A7: 2021 | B7: ='Data Tahunan'!K2 -> 22849394 | C7: 1696 | D7: 170 | E7: =188484+122271 -> 310755 | F7: 59887.526 | G7: 27.48 | H7: 12097.19 | I7: 848.8042 | J7: 7379577
A8: 2022 | B8: ='Data Tahunan'!L2 -> 25755726 | C8: 1818 | D8: 183 | E8: =255614+139670 -> 395284 | F8: 57709.076 | G8: 44.99 | H8: 13672.58 | I8: 463.5886 | J8: 9267217
A9: 2023 | B9: ='Data Tahunan'!M2 -> 30542580 | C9: 1820 | D9: 201 | E9: =122273+237067 -> 359340 | F9: 75624.404 | G9: 44.77 | H9: 14809.2 | I9: 1175.2552 | J9: 11417702
A10: 2024 | B10: ='Data Tahunan'!N2 -> 38134536 | C10: 2000 | D10: 218 | E10: =227695+123251 -> 350946 | F10: 73511.575 | G10: 42.17 | H10: 15873.81 | I10: 712.2835 | J10: 11503540
A11: 2025 | B11: ='Data Tahunan'!O2 -> 40695654 | C11: 2291 | D11: 201 | E11: =242091+122903 -> 364994 | F11: 55029.535 | G11: 38.07 | H11: 16947.62 | I11: 1325.9504 | J11: 11954114
A13: Tahun Covid
